<?xml version="1.0" encoding="UTF-8"?>
<testsuite name="nosetests" tests="3" errors="1" failures="1" skip="0">
  <testcase classname="test_sample1" name="test_successfull" time="0.000" />
  <testcase classname="test_sample1" name="test_failed" time="0.000">
    <failure type="exceptions.AssertionError" message=""><![CDATA[Traceback (most recent call last):
    File "/usr/lib/python2.7/unittest/case.py", line 327, in run
    testMethod()
    File "/usr/lib/python2.7/dist-packages/nose/case.py", line 197, in runTest
    self.test(*self.arg)
    File "/home/wen/src/test-projects/sonar-examples/projects/languages/python/python-sonar-runner/src/tests/test_sample.py", line 7, in test_failed
    assert False
    AssertionError
    ]]></failure>
  </testcase>
  <testcase classname="test_sample1" name="test_error" time="0.000">
    <error type="exceptions.NameError" message="global name 'not_exising_callable' is not defined"><![CDATA[Traceback (most recent call last):
    File "/usr/lib/python2.7/unittest/case.py", line 327, in run
    testMethod()
    File "/usr/lib/python2.7/dist-packages/nose/case.py", line 197, in runTest
    self.test(*self.arg)
    File "/home/wen/src/test-projects/sonar-examples/projects/languages/python/python-sonar-runner/src/tests/test_sample.py", line 10, in test_error
    not_exising_callable()
    NameError: global name 'not_exising_callable' is not defined
    ]]></error>
  </testcase>
</testsuite>
